<?xml version="1.0" ?>
<!-- =================================================================================== -->
<!-- |    This document was autogenerated by xacro from /home/anubhav1772/catkin_ws/src/ow_robotic_arm/owr_description/urdf/gripper/owr_robotiq_140.xacro | -->
<!-- |    EDITING THIS FILE BY HAND IS NOT RECOMMENDED                                 | -->
<!-- =================================================================================== -->
<robot name="owr_gripper">
    <gazebo>
        <plugin filename="libgazebo_ros_control.so" name="ros_control">
            <legacyModeNS>true</legacyModeNS>
            <robotNamespace>/</robotNamespace>
            <robotSimType>gazebo_ros_control/DefaultRobotHWSim</robotSimType>
        </plugin>
        <plugin name="gazebo_ros_control">
            <robotNamespace>/</robotNamespace>
        </plugin>
    </gazebo>
    <!-- <gazebo reference="camera_link">
    <sensor type="depth" name="camera">
        <always_on>true</always_on>
        <visualize>false</visualize>
        <update_rate>15.0</update_rate>
        <camera name="front">
            <horizontal_fov>1.047197</horizontal_fov>
            <image>
                <format>B8G8R8</format>
                <width>640</width>
                <height>480</height>
            </image>
            <clip>
                <near>0.01</near>
                <far>9</far>
            </clip>
        </camera>
        <plugin name="camera_plugin" filename="libgazebo_ros_openni_kinect.so">
          <baseline>0.1</baseline>
          <alwaysOn>true</alwaysOn> 
          <updateRate>15.0</updateRate>
          <cameraName>camera</cameraName>
          <imageTopicName>/camera/rgb/image_raw</imageTopicName>
          <cameraInfoTopicName>/camera/rgb/camera_info</cameraInfoTopicName>
          <depthImageTopicName>/camera/depth_registered/image_raw</depthImageTopicName>
          <depthImageCameraInfoTopicName>/camera/depth_registered/camera_info</depthImageCameraInfoTopicName>
          <pointCloudTopicName>/camera/depth_registered/points</pointCloudTopicName>
          <frameName>camera_rgb_optical_frame</frameName>
          <pointCloudCutoff>0.35</pointCloudCutoff>
          <pointCloudCutoffMax>4.5</pointCloudCutoffMax>
          <CxPrime>0</CxPrime>
          <Cx>0</Cx>
          <Cy>0</Cy>
          <focalLength>0</focalLength>
          <hackBaseline>0</hackBaseline>
        </plugin>
    </sensor> 
  </gazebo>  -->
    <!-- Inertia parameters -->
    <!-- With soft limits -->
    <!-- 
        <xacro:property name="BJ_lower_limit" value="-2.0944" />
        <xacro:property name="BJ_upper_limit" value="2.0944" />
        <xacro:property name="SJ_lower_limit" value="-1.5708" />
        <xacro:property name="SJ_upper_limit" value="1.5708" />
        <xacro:property name="EJ_lower_limit" value="-3.92699" />
        <xacro:property name="EJ_upper_limit" value="1.0472" />
        <xacro:property name="W1J_lower_limit" value="-1.5708" />
        <xacro:property name="W1J_upper_limit" value="1.5708" />
        <xacro:property name="W2J_lower_limit" value="-1.0472" />
        <xacro:property name="W2J_upper_limit" value="2.618" />
        <xacro:property name="W3J_lower_limit" value="${-pi}" />
        <xacro:property name="W3J_upper_limit" value="${pi}" /> 
    -->
    <!-- 
        <xacro:property name="bl_stl" value="package://owr_description/meshes/base_link.STL" />
        <xacro:property name="bsl_stl" value="package://owr_description/meshes/BS.STL" />
        <xacro:property name="sel_stl" value="package://owr_description/meshes/BE.STL" />
        <xacro:property name="ew1l_stl" value="package://owr_description/meshes/EW1.STL" />
        <xacro:property name="w1w2l_stl" value="package://owr_description/meshes/W12.STL" />
        <xacro:property name="w2w3l_stl" value="package://owr_description/meshes/W23.STL" />
        <xacro:property name="w3eefl_stl" value="package://owr_description/meshes/W3Eff.STL" /> 
    -->
    <transmission name="BJ_trans">
        <type>transmission_interface/SimpleTransmission</type>
        <joint name="BJ">
            <hardwareInterface>hardware_interface/PositionJointInterface</hardwareInterface>
        </joint>
        <actuator name="BJ_motor">
            <mechanicalReduction>1</mechanicalReduction>
            <hardwareInterface>hardware_interface/EffortJointInterface</hardwareInterface>
        </actuator>
    </transmission>
    <transmission name="SJ_trans">
        <type>transmission_interface/SimpleTransmission</type>
        <joint name="SJ">
            <hardwareInterface>hardware_interface/PositionJointInterface</hardwareInterface>
        </joint>
        <actuator name="SJ_motor">
            <mechanicalReduction>1</mechanicalReduction>
            <hardwareInterface>hardware_interface/EffortJointInterface</hardwareInterface>
        </actuator>
    </transmission>
    <transmission name="EJ_trans">
        <type>transmission_interface/SimpleTransmission</type>
        <joint name="EJ">
            <hardwareInterface>hardware_interface/PositionJointInterface</hardwareInterface>
        </joint>
        <actuator name="EJ_motor">
            <mechanicalReduction>1</mechanicalReduction>
            <hardwareInterface>hardware_interface/EffortJointInterface</hardwareInterface>
        </actuator>
    </transmission>
    <transmission name="W1J_trans">
        <type>transmission_interface/SimpleTransmission</type>
        <joint name="W1J">
            <hardwareInterface>hardware_interface/PositionJointInterface</hardwareInterface>
        </joint>
        <actuator name="W1J_motor">
            <mechanicalReduction>1</mechanicalReduction>
            <hardwareInterface>hardware_interface/EffortJointInterface</hardwareInterface>
        </actuator>
    </transmission>
    <transmission name="W2J_trans">
        <type>transmission_interface/SimpleTransmission</type>
        <joint name="W2J">
            <hardwareInterface>hardware_interface/PositionJointInterface</hardwareInterface>
        </joint>
        <actuator name="W2J_motor">
            <mechanicalReduction>1</mechanicalReduction>
            <hardwareInterface>hardware_interface/EffortJointInterface</hardwareInterface>
        </actuator>
    </transmission>
    <transmission name="W3J_trans">
        <type>transmission_interface/SimpleTransmission</type>
        <joint name="W3J">
            <hardwareInterface>hardware_interface/PositionJointInterface</hardwareInterface>
        </joint>
        <actuator name="W3J_motor">
            <mechanicalReduction>1</mechanicalReduction>
            <hardwareInterface>hardware_interface/EffortJointInterface</hardwareInterface>
        </actuator>
    </transmission>
    <gazebo reference="base_link">
        <selfCollide>true</selfCollide>
    </gazebo>
    <gazebo reference="BS_Link">
        <selfCollide>true</selfCollide>
    </gazebo>
    <gazebo reference="SE_Link">
        <selfCollide>true</selfCollide>
    </gazebo>
    <gazebo reference="EW1_Link">
        <selfCollide>true</selfCollide>
    </gazebo>
    <gazebo reference="W1W2_Link">
        <selfCollide>true</selfCollide>
    </gazebo>
    <gazebo reference="W2W3_Link">
        <selfCollide>true</selfCollide>
    </gazebo>
    <gazebo reference="W3EEF_Link">
        <selfCollide>true</selfCollide>
    </gazebo>
    <gazebo reference="EEF_Link">
        <selfCollide>true</selfCollide>
    </gazebo>
    <link name="base_link">
        <inertial>
            <origin rpy="0 0 0" xyz="3.26945350830445E-18 0.0475560449135545 1.03923298601914E-18" />
            <mass value="2.00431395827099" />
            <inertia ixx="0.00559780558915754" ixy="2.08121312953797E-19" ixz="-2.03088203267664E-36" iyy="0.00632266595300574" iyz="3.02972434618886E-20" izz="0.00559780558915754" />
        </inertial>
        <visual>
            <origin rpy="0 0 0" xyz="0 0 0" />
            <geometry>
                <mesh filename="file:///home/anubhav1772/catkin_ws/src/ow_robotic_arm/owr_description/meshes/collision/base_link.STL" />
            </geometry>
            <geometry>
                <mesh filename="file:///home/anubhav1772/catkin_ws/src/ow_robotic_arm/owr_description/meshes/visual/base.dae" />
            </geometry>
            <material name="">
                <color rgba="0.439216 0.47451 0.501961 1.0" />
            </material>
        </visual>
        <collision>
            <origin rpy="0 0 0" xyz="0 0 0" />
            <geometry>
                <mesh filename="file:///home/anubhav1772/catkin_ws/src/ow_robotic_arm/owr_description/meshes/collision/base_link.STL" />
            </geometry>
        </collision>
    </link>
    <joint name="BJ" type="revolute">
        <origin rpy="0 0 0" xyz="0 0 0.1181" />
        <parent link="base_link" />
        <child link="BS_Link" />
        <axis xyz="0 0 1" />
        <limit effort="200" lower="-2.0943951023931953" upper="2.0943951023931953" velocity="5" />
        <!-- <safety_controller soft_lower="${BJ_lower_limit+0.1}" soft_upper="${BJ_upper_limit-0.1}" k_velocity="0" /> -->
        <!-- particularly useful for simulation -->
        <dynamics damping="0.0" friction="0.0" />
    </joint>
    <link name="BS_Link">
        <inertial>
            <origin rpy="0 0 0" xyz="-2.23815285813307E-07 0.0379790003524418 0.0624393623259869" />
            <mass value="1.97583366234436" />
            <inertia ixx="0.00633633680688803" ixy="5.53297653948722E-09" ixz="1.10027473238432E-08" iyy="0.00431174755033153" iyz="-0.00121307806869219" izz="0.00588373141716525" />
        </inertial>
        <visual>
            <origin rpy="0 0 0" xyz="0 0 0" />
            <geometry>
                <mesh filename="file:///home/anubhav1772/catkin_ws/src/ow_robotic_arm/owr_description/meshes/collision/BS_Link.STL" />
            </geometry>
            <!-- <geometry>
                    <mesh filename="${bsl_dae}"/>
                </geometry> -->
            <material name="">
                <color rgba="0.866667 0.321569 0.156863 1.0" />
            </material>
        </visual>
        <collision>
            <origin rpy="0 0 0" xyz="0 0 0" />
            <geometry>
                <mesh filename="file:///home/anubhav1772/catkin_ws/src/ow_robotic_arm/owr_description/meshes/collision/BS_Link.STL" />
            </geometry>
        </collision>
    </link>
    <joint name="SJ" type="revolute">
        <origin rpy="0 0 0" xyz="0 0.1157 0.0775" />
        <parent link="BS_Link" />
        <child link="SE_Link" />
        <axis xyz="0 1 0" />
        <limit effort="200" lower="-1.5707963267948966" upper="1.5707963267948966" velocity="5" />
        <!-- <safety_controller soft_lower="${SJ_lower_limit+0.03}" soft_upper="${SJ_upper_limit-0.03}" k_velocity="0" /> -->
        <!-- particularly useful for simulation -->
        <dynamics damping="0.0" friction="0.0" />
    </joint>
    <link name="SE_Link">
        <inertial>
            <origin rpy="0 0 0" xyz="2.50150839169102E-18 0.0491871756151301 0.177875" />
            <mass value="6.92438507119168" />
            <inertia ixx="0.13565458366121" ixy="1.62637671478552E-19" ixz="-3.10060648119612E-18" iyy="0.141881889957825" iyz="1.26283834369711E-17" izz="0.01733034956749" />
        </inertial>
        <visual>
            <origin rpy="0 0 0" xyz="0 0 0" />
            <!-- <geometry>
                    <mesh filename="${sel_dae}"/>
                </geometry> -->
            <geometry>
                <mesh filename="file:///home/anubhav1772/catkin_ws/src/ow_robotic_arm/owr_description/meshes/collision/SE_Link.STL" />
            </geometry>
            <material name="">
                <color rgba="1 0.756863 0.054902 1.0" />
            </material>
        </visual>
        <collision>
            <origin rpy="0 0 0" xyz="0 0 0" />
            <geometry>
                <mesh filename="file:///home/anubhav1772/catkin_ws/src/ow_robotic_arm/owr_description/meshes/collision/SE_Link.STL" />
            </geometry>
        </collision>
    </link>
    <joint name="EJ" type="revolute">
        <origin rpy="0 0 0" xyz="0 0 0.35575" />
        <parent link="SE_Link" />
        <child link="EW1_Link" />
        <axis xyz="0 1 0" />
        <limit effort="200" lower="-3.9269908169872414" upper="1.0471975511965976" velocity="5" />
        <!-- <safety_controller soft_lower="${EJ_lower_limit+0.1}" soft_upper="${EJ_upper_limit-0.1}" k_velocity="0" /> -->
        <!-- particularly useful for simulation -->
        <dynamics damping="0.0" friction="0.0" />
    </joint>
    <link name="EW1_Link">
        <inertial>
            <origin rpy="0 0 0" xyz="0.00964296883173089 -0.069409712721787 6.49394750775745E-05" />
            <mass value="1.64092408380158" />
            <inertia ixx="0.00433302226551719" ixy="0.000795034760133281" ixz="2.13272246028262E-07" iyy="0.00315022911015594" iyz="2.61373190609785E-06" izz="0.004670087340654" />
        </inertial>
        <visual>
            <origin rpy="0 0 0" xyz="0 0 0" />
            <!-- <geometry>
                    <mesh filename="${ew1l_dae}"/>
                </geometry> -->
            <geometry>
                <mesh filename="file:///home/anubhav1772/catkin_ws/src/ow_robotic_arm/owr_description/meshes/collision/EW1_Link.STL" />
            </geometry>
            <material name="">
                <color rgba="0.372549 0.654902 0.239216 1.0" />
            </material>
        </visual>
        <collision>
            <origin rpy="0 0 0" xyz="0 0 0" />
            <geometry>
                <mesh filename="file:///home/anubhav1772/catkin_ws/src/ow_robotic_arm/owr_description/meshes/collision/EW1_Link.STL" />
            </geometry>
        </collision>
    </link>
    <joint name="W1J" type="revolute">
        <origin rpy="0 0 0" xyz="0.0695 -0.1157 0" />
        <parent link="EW1_Link" />
        <child link="W1W2_Link" />
        <axis xyz="1 0 0" />
        <limit effort="200" lower="-1.5707963267948966" upper="1.5707963267948966" velocity="5" />
        <!-- <safety_controller soft_lower="${W1J_lower_limit+0.03}" soft_upper="${W1J_upper_limit-0.03}" k_velocity="0" /> -->
        <!-- particularly useful for simulation -->
        <dynamics damping="0.0" friction="0.0" />
    </joint>
    <link name="W1W2_Link">
        <inertial>
            <origin rpy="0 0 0" xyz="0.122416824512388 -0.070835232118926 -6.35496342438202E-07" />
            <mass value="2.38378471545783" />
            <inertia ixx="0.00656420598358183" ixy="0.00554676162331256" ixz="-1.42658921336938E-08" iyy="0.0257284659921832" iyz="5.99320555321235E-08" izz="0.0282762053128848" />
        </inertial>
        <visual>
            <origin rpy="0 0 0" xyz="0 0 0" />
            <!-- <geometry>
                    <mesh filename="${w1w2l_dae}"/>
                </geometry> -->
            <geometry>
                <mesh filename="file:///home/anubhav1772/catkin_ws/src/ow_robotic_arm/owr_description/meshes/collision/W12_Link.STL" />
            </geometry>
            <material name="">
                <color rgba="0.32549 0.529412 0.752941 1.0" />
            </material>
        </visual>
        <collision>
            <origin rpy="0 0 0" xyz="0 0 0" />
            <geometry>
                <mesh filename="file:///home/anubhav1772/catkin_ws/src/ow_robotic_arm/owr_description/meshes/collision/W12_Link.STL" />
            </geometry>
        </collision>
    </link>
    <joint name="W2J" type="revolute">
        <origin rpy="0 0 0" xyz="0.28625 0 0" />
        <parent link="W1W2_Link" />
        <child link="W2W3_Link" />
        <axis xyz="0 1 0" />
        <limit effort="200" lower="-1.0471975511965976" upper="2.6179938779914944" velocity="5" />
        <!-- <safety_controller soft_lower="${W2J_lower_limit+0.03}" soft_upper="${W2J_upper_limit-0.1}" k_velocity="0" /> -->
        <!-- particularly useful for simulation -->
        <dynamics damping="0.0" friction="0.0" />
    </joint>
    <link name="W2W3_Link">
        <inertial>
            <origin rpy="0 0 0" xyz="0.00448693932692878 -0.00693126827424433 0.0578431512744524" />
            <mass value="2.16776601749277" />
            <inertia ixx="0.00982478610028387" ixy="-6.74414524982295E-05" ixz="-0.000653082358596031" iyy="0.00957809977704417" iyz="-0.000917655229213172" izz="0.00385756520688612" />
        </inertial>
        <visual>
            <origin rpy="0 0 0" xyz="0 0 0" />
            <!-- <geometry>
                    <mesh filename="${w2w3l_dae}"/>
                </geometry> -->
            <geometry>
                <mesh filename="file:///home/anubhav1772/catkin_ws/src/ow_robotic_arm/owr_description/meshes/collision/W23_Link.STL" />
            </geometry>
            <material name="">
                <color rgba="0.513725 0.415686 0.733333 1.0" />
            </material>
        </visual>
        <collision>
            <origin rpy="0 0 0" xyz="0 0 0" />
            <geometry>
                <mesh filename="file:///home/anubhav1772/catkin_ws/src/ow_robotic_arm/owr_description/meshes/collision/W23_Link.STL" />
            </geometry>
        </collision>
    </link>
    <joint name="W3J" type="revolute">
        <origin rpy="0 0 0" xyz="0.0635 0 0.12" />
        <parent link="W2W3_Link" />
        <child link="W3EEF_Link" />
        <axis xyz="1 0 0" />
        <limit effort="200" lower="-3.141592653589793" upper="3.141592653589793" velocity="5" />
        <!-- <safety_controller soft_lower="${W3J_lower_limit+0.01}" soft_upper="${W3J_upper_limit-0.01}" k_velocity="0" /> -->
        <!-- particularly useful for simulation -->
        <dynamics damping="0.0" friction="0.0" />
    </joint>
    <link name="W3EEF_Link">
        <inertial>
            <origin rpy="0 0 0" xyz="0.0313921684941835 5.73430521827697E-08 -7.81709305108791E-06" />
            <mass value="0.542548240711207" />
            <inertia ixx="0.00073681574143187" ixy="8.23684417617962E-22" ixz="1.40415282317197E-07" iyy="0.000548089226198482" iyz="3.0678420032912E-20" izz="0.000548195288104005" />
        </inertial>
        <visual>
            <origin rpy="0 0 0" xyz="0 0 0" />
            <!-- <geometry>
                    <mesh filename="${w3eefl_dae}"/>
                </geometry> -->
            <geometry>
                <mesh filename="file:///home/anubhav1772/catkin_ws/src/ow_robotic_arm/owr_description/meshes/collision/W3Eff_Link.STL" />
            </geometry>
            <material name="">
                <color rgba="0.901961 0.901961 0.901961 1.0" />
            </material>
        </visual>
        <collision>
            <origin rpy="0 0 0" xyz="0 0 0" />
            <geometry>
                <mesh filename="file:///home/anubhav1772/catkin_ws/src/ow_robotic_arm/owr_description/meshes/collision/W3Eff_Link.STL" />
            </geometry>
        </collision>
    </link>
    <!--<link name="${prefix}EEF_Link"/>-->
    <joint name="eef_fixed_joint" type="fixed">
        <parent link="W3EEF_Link" />
        <child link="EEF_Link" />
        <origin rpy="0 0 0" xyz="0.0675 0 0" />
    </joint>
    <link name="EEF_Link">
        <collision>
            <geometry>
                <box size="0.001 0.001 0.001" />
            </geometry>
            <origin rpy="0 0 0" xyz="0 0 0" />
        </collision>
        <visual>
            <origin rpy="0 0 0" xyz="0 0 0" />
            <geometry>
                <box size="0.001 0.001 0.001" />
            </geometry>
            <material name="">
                <color rgba="1 0 0 1.0" />
            </material>
        </visual>
        <inertial>
            <mass value="0.1" />
            <origin xyz="0 0 0" rpy="0 0 0" />
            <inertia ixx="0.03" iyy="0.03" izz="0.03" ixy="0.0" ixz="0.0" iyz="0.0" />
        </inertial>
    </link>
    <link name="world" />
    <!--Note that the object is fixed to the world at the position 
        we specify in the joint, not the parameters we give to spawn_model -->
    <joint name="world_joint" type="fixed">
        <parent link="world" />
        <child link="base_link" />
        <origin rpy="0.0 0.0 0.0" xyz="0.0 0.0 0.75" />
    </joint>
    <!-- mount the fts to the robot -->
    <joint name="fts_fix" type="fixed">
        <!--In most cases origin would be flange adapter plate: <origin xyz="0 0 0.009" rpy="0 0 0"/> /-->
        <origin rpy="-1.5707963267948966 0 -1.5707963267948966" xyz="0.009 0 0 " />
        <parent link="EEF_Link" />
        <child link="fts_robotside" />
    </joint>
    <link name="fts_robotside">
        <inertial>
            <origin rpy="0 0 0" xyz="0 0 0.01875" />
            <mass value="0.65" />
            <inertia ixx="0.000661171875" ixy="0" ixz="0" iyy="0.000661171875" iyz="0" izz="0.00117" />
        </inertial>
        <visual>
            <origin rpy="0 0 0" xyz="0 0 0" />
            <geometry>
                <mesh filename="package://owr_description/meshes/gripper/robotiq_fts150.stl" scale="0.6 0.6 1.0" />
            </geometry>
            <material name="black">
                <color rgba="0.0 0.0 0.0 1.0" />
            </material>
        </visual>
        <collision>
            <origin rpy="0 0 0" xyz="0 0 0" />
            <geometry>
                <mesh filename="package://owr_description/meshes/gripper/robotiq_fts150.stl" scale="0.6 0.6 1.0" />
            </geometry>
        </collision>
    </link>
    <!-- virtual measurement frame -->
    <joint name="measurment_joint" type="fixed">
        <origin rpy="0 0 0" xyz="0 0 0.01625" />
        <parent link="fts_robotside" />
        <child link="robotiq_force_torque_frame_id" />
    </joint>
    <link name="robotiq_force_torque_frame_id" />
    <!-- toolside frame -->
    <joint name="toolside_joint" type="fixed">
        <origin rpy="0 0 0" xyz="0 0 0.0375" />
        <parent link="fts_robotside" />
        <child link="fts_toolside" />
    </joint>
    <link name="fts_toolside" />
    <link name="robotiq_arg2f_base_link">
        <inertial>
            <origin rpy="0 0 0" xyz="8.625E-08 -4.6583E-06 0.03145" />
            <mass value="0.22652" />
            <inertia ixx="0.00020005" ixy="-4.2442E-10" ixz="-2.9069E-10" iyy="0.00017832" iyz="-3.4402E-08" izz="0.00013478" />
        </inertial>
        <visual>
            <origin rpy="0 0 0" xyz="0 0 0" />
            <geometry>
                <mesh filename="package://owr_description/meshes/gripper/robotiq_arg2f_base_link_fine.stl" />
            </geometry>
            <material name="">
                <color rgba="0.1 0.1 0.1 1" />
            </material>
        </visual>
        <collision>
            <origin rpy="0 0 1.5707963267948966" xyz="0 0 0" />
            <geometry>
                <mesh filename="package://owr_description/meshes/gripper/robotiq_arg2f_base_link_coarse.stl" />
            </geometry>
        </collision>
    </link>
    <!--<gazebo reference="${prefix}robotiq_arg2f_base_link">
      <selfCollide>true</selfCollide>
      <gravity>false</gravity>
      <implicitSpringDamper>1</implicitSpringDamper>
      <mu1>100000</mu1>
      <mu2>100000</mu2>
      <kp>100000000.0</kp>
      <kd>1.0</kd>
    </gazebo>-->
    <link name="left_outer_knuckle">
        <inertial>
            <origin rpy="0 0 0" xyz="-0.000200000000003065 0.0199435877845359 0.0292245259211331" />
            <mass value="0.00853198276973456" />
            <inertia ixx="2.89328108496468E-06" ixy="-1.57935047237397E-19" ixz="-1.93980378593255E-19" iyy="1.86719750325683E-06" iyz="-1.21858577871576E-06" izz="1.21905238907251E-06" />
        </inertial>
        <visual>
            <origin rpy="0 0 0" xyz="0 0 0" />
            <geometry>
                <mesh filename="package://owr_description/meshes/gripper/robotiq_arg2f_140_outer_knuckle.stl" />
            </geometry>
            <material name="">
                <color rgba="0.792156862745098 0.819607843137255 0.933333333333333 1" />
            </material>
        </visual>
        <collision>
            <origin rpy="0 0 0" xyz="0 0 0" />
            <geometry>
                <mesh filename="package://owr_description/meshes/gripper/robotiq_arg2f_140_outer_knuckle.stl" />
            </geometry>
        </collision>
    </link>
    <!--<gazebo reference="${prefix}${fingerprefix}_outer_knuckle">
      <selfCollide>true</selfCollide>
      <gravity>false</gravity>
      <implicitSpringDamper>1</implicitSpringDamper>
      <mu1>100000</mu1>
      <mu2>100000</mu2>
      <kp>100000000.0</kp>
      <kd>1.0</kd>
      <maxVel>0</maxVel>
    </gazebo>-->
    <link name="left_outer_finger">
        <inertial>
            <origin rpy="0 0 0" xyz="0.00030115855001899 0.0373907951953854 -0.0208027427000385" />
            <mass value="0.022614240507152" />
            <inertia ixx="1.52518312458174E-05" ixy="9.76583423954399E-10" ixz="-5.43838577022588E-10" iyy="6.17694243867776E-06" iyz="6.78636130740228E-06" izz="1.16494917907219E-05" />
        </inertial>
        <visual>
            <origin rpy="0 0 0" xyz="0 0 0" />
            <geometry>
                <mesh filename="package://owr_description/meshes/gripper/robotiq_arg2f_140_outer_finger.stl" />
            </geometry>
            <material name="">
                <color rgba="0.1 0.1 0.1 1" />
            </material>
        </visual>
        <collision>
            <origin rpy="0 0 0" xyz="0 0 0" />
            <geometry>
                <mesh filename="package://owr_description/meshes/gripper/robotiq_arg2f_140_outer_finger.stl" />
            </geometry>
        </collision>
    </link>
    <!--<gazebo reference="${prefix}${fingerprefix}_outer_finger">
      <selfCollide>true</selfCollide>
      <gravity>false</gravity>
      <implicitSpringDamper>1</implicitSpringDamper>
      <mu1>100000</mu1>
      <mu2>100000</mu2>
      <kp>100000000.0</kp>
      <kd>1.0</kd>
    </gazebo>-->
    <link name="left_inner_finger">
        <inertial>
            <origin rpy="0 0 0" xyz="0.000299999999999317 0.0160078233491243 -0.0136945669206257" />
            <mass value="0.0104003125914103" />
            <inertia ixx="2.71909453810972E-06" ixy="1.35402465472579E-21" ixz="-7.1817349065269E-22" iyy="7.69100314106116E-07" iyz="6.74715432769696E-07" izz="2.30315190420171E-06" />
        </inertial>
        <visual>
            <origin rpy="0 0 0" xyz="0 0 0" />
            <geometry>
                <mesh filename="package://owr_description/meshes/gripper/robotiq_arg2f_140_inner_finger.stl" />
            </geometry>
            <material name="">
                <color rgba="0.1 0.1 0.1 1" />
            </material>
        </visual>
        <collision>
            <origin rpy="0 0 0" xyz="0 0 0" />
            <geometry>
                <mesh filename="package://owr_description/meshes/gripper/robotiq_arg2f_140_inner_finger.stl" />
            </geometry>
        </collision>
    </link>
    <!--<gazebo reference="${prefix}${fingerprefix}_inner_finger">
      <selfCollide>true</selfCollide>
      <gravity>false</gravity>
      <implicitSpringDamper>1</implicitSpringDamper>
      <mu1>100000</mu1>
      <mu2>100000</mu2>
      <kp>100000000.0</kp>
      <kd>1.0</kd>
    </gazebo>-->
    <link name="left_inner_knuckle">
        <inertial>
            <origin rpy="0 0 0" xyz="0.000123011831763771 0.0507850843201817 0.00103968640075166" />
            <mass value="0.0271177346495152" />
            <inertia ixx="2.61910379223783E-05" ixy="-2.43616858946494E-07" ixz="-6.37789906117123E-09" iyy="2.8270243746167E-06" iyz="-5.37200748039765E-07" izz="2.83695868220296E-05" />
        </inertial>
        <visual>
            <origin rpy="0 0 0" xyz="0 0 0" />
            <geometry>
                <mesh filename="package://owr_description/meshes/gripper/robotiq_arg2f_140_inner_knuckle.stl" />
            </geometry>
            <material name="">
                <color rgba="0.1 0.1 0.1 1" />
            </material>
        </visual>
        <collision>
            <origin rpy="0 0 0" xyz="0 0 0" />
            <geometry>
                <mesh filename="package://owr_description/meshes/gripper/robotiq_arg2f_140_inner_knuckle.stl" />
            </geometry>
        </collision>
    </link>
    <!--<gazebo reference="${prefix}${fingerprefix}_inner_knuckle">
      <selfCollide>true</selfCollide>
      <gravity>false</gravity>
      <implicitSpringDamper>1</implicitSpringDamper>
      <mu1>100000</mu1>
      <mu2>100000</mu2>
      <kp>100000000.0</kp>
      <kd>1.0</kd>
    </gazebo>-->
    <link name="left_finger_tip">
        <inertial>
            <origin rpy="0 0 0" xyz="0.000299999999999317 0.0160078233491243 -0.0136945669206257" />
            <mass value="0.0104003125914103" />
            <inertia ixx="2.71909453810972E-06" ixy="0.0" ixz="0.0" iyy="7.69100314106116E-07" iyz="0.0" izz="2.30315190420171E-06" />
        </inertial>
        <visual>
            <origin rpy="0 0 0" xyz="0 0.02 -0.05" />
            <geometry>
                <mesh filename="package://owr_description/meshes/gripper/robotiq_arg2f_140_finger_tip.dae" scale="1.0 1.0 1.0" />
            </geometry>
            <material name="">
                <color rgba="0.1 0.1 0.1 1" />
            </material>
        </visual>
        <collision>
            <origin rpy="0 0 0" xyz="0 0 0" />
            <geometry>
                <mesh filename="package://owr_description/meshes/gripper/robotiq_arg2f_140_finger_tip.dae" scale="1.0 1.0 1.0" />
            </geometry>
        </collision>
    </link>
    <!--<gazebo reference="${prefix}${fingerprefix}_finger_tip">
      <selfCollide>true</selfCollide>
      <gravity>false</gravity>
      <implicitSpringDamper>1</implicitSpringDamper>
      <mu1>100000</mu1>
      <mu2>100000</mu2>
      <kp>100000000.0</kp>
      <kd>1.0</kd>
    </gazebo>-->
    <link name="right_outer_knuckle">
        <inertial>
            <origin rpy="0 0 0" xyz="-0.000200000000003065 0.0199435877845359 0.0292245259211331" />
            <mass value="0.00853198276973456" />
            <inertia ixx="2.89328108496468E-06" ixy="-1.57935047237397E-19" ixz="-1.93980378593255E-19" iyy="1.86719750325683E-06" iyz="-1.21858577871576E-06" izz="1.21905238907251E-06" />
        </inertial>
        <visual>
            <origin rpy="0 0 0" xyz="0 0 0" />
            <geometry>
                <mesh filename="package://owr_description/meshes/gripper/robotiq_arg2f_140_outer_knuckle.stl" />
            </geometry>
            <material name="">
                <color rgba="0.792156862745098 0.819607843137255 0.933333333333333 1" />
            </material>
        </visual>
        <collision>
            <origin rpy="0 0 0" xyz="0 0 0" />
            <geometry>
                <mesh filename="package://owr_description/meshes/gripper/robotiq_arg2f_140_outer_knuckle.stl" />
            </geometry>
        </collision>
    </link>
    <!--<gazebo reference="${prefix}${fingerprefix}_outer_knuckle">
      <selfCollide>true</selfCollide>
      <gravity>false</gravity>
      <implicitSpringDamper>1</implicitSpringDamper>
      <mu1>100000</mu1>
      <mu2>100000</mu2>
      <kp>100000000.0</kp>
      <kd>1.0</kd>
      <maxVel>0</maxVel>
    </gazebo>-->
    <link name="right_outer_finger">
        <inertial>
            <origin rpy="0 0 0" xyz="0.00030115855001899 0.0373907951953854 -0.0208027427000385" />
            <mass value="0.022614240507152" />
            <inertia ixx="1.52518312458174E-05" ixy="9.76583423954399E-10" ixz="-5.43838577022588E-10" iyy="6.17694243867776E-06" iyz="6.78636130740228E-06" izz="1.16494917907219E-05" />
        </inertial>
        <visual>
            <origin rpy="0 0 0" xyz="0 0 0" />
            <geometry>
                <mesh filename="package://owr_description/meshes/gripper/robotiq_arg2f_140_outer_finger.stl" />
            </geometry>
            <material name="">
                <color rgba="0.1 0.1 0.1 1" />
            </material>
        </visual>
        <collision>
            <origin rpy="0 0 0" xyz="0 0 0" />
            <geometry>
                <mesh filename="package://owr_description/meshes/gripper/robotiq_arg2f_140_outer_finger.stl" />
            </geometry>
        </collision>
    </link>
    <!--<gazebo reference="${prefix}${fingerprefix}_outer_finger">
      <selfCollide>true</selfCollide>
      <gravity>false</gravity>
      <implicitSpringDamper>1</implicitSpringDamper>
      <mu1>100000</mu1>
      <mu2>100000</mu2>
      <kp>100000000.0</kp>
      <kd>1.0</kd>
    </gazebo>-->
    <link name="right_inner_finger">
        <inertial>
            <origin rpy="0 0 0" xyz="0.000299999999999317 0.0160078233491243 -0.0136945669206257" />
            <mass value="0.0104003125914103" />
            <inertia ixx="2.71909453810972E-06" ixy="1.35402465472579E-21" ixz="-7.1817349065269E-22" iyy="7.69100314106116E-07" iyz="6.74715432769696E-07" izz="2.30315190420171E-06" />
        </inertial>
        <visual>
            <origin rpy="0 0 0" xyz="0 0 0" />
            <geometry>
                <mesh filename="package://owr_description/meshes/gripper/robotiq_arg2f_140_inner_finger.stl" />
            </geometry>
            <material name="">
                <color rgba="0.1 0.1 0.1 1" />
            </material>
        </visual>
        <collision>
            <origin rpy="0 0 0" xyz="0 0 0" />
            <geometry>
                <mesh filename="package://owr_description/meshes/gripper/robotiq_arg2f_140_inner_finger.stl" />
            </geometry>
        </collision>
    </link>
    <!--<gazebo reference="${prefix}${fingerprefix}_inner_finger">
      <selfCollide>true</selfCollide>
      <gravity>false</gravity>
      <implicitSpringDamper>1</implicitSpringDamper>
      <mu1>100000</mu1>
      <mu2>100000</mu2>
      <kp>100000000.0</kp>
      <kd>1.0</kd>
    </gazebo>-->
    <link name="right_inner_knuckle">
        <inertial>
            <origin rpy="0 0 0" xyz="0.000123011831763771 0.0507850843201817 0.00103968640075166" />
            <mass value="0.0271177346495152" />
            <inertia ixx="2.61910379223783E-05" ixy="-2.43616858946494E-07" ixz="-6.37789906117123E-09" iyy="2.8270243746167E-06" iyz="-5.37200748039765E-07" izz="2.83695868220296E-05" />
        </inertial>
        <visual>
            <origin rpy="0 0 0" xyz="0 0 0" />
            <geometry>
                <mesh filename="package://owr_description/meshes/gripper/robotiq_arg2f_140_inner_knuckle.stl" />
            </geometry>
            <material name="">
                <color rgba="0.1 0.1 0.1 1" />
            </material>
        </visual>
        <collision>
            <origin rpy="0 0 0" xyz="0 0 0" />
            <geometry>
                <mesh filename="package://owr_description/meshes/gripper/robotiq_arg2f_140_inner_knuckle.stl" />
            </geometry>
        </collision>
    </link>
    <!--<gazebo reference="${prefix}${fingerprefix}_inner_knuckle">
      <selfCollide>true</selfCollide>
      <gravity>false</gravity>
      <implicitSpringDamper>1</implicitSpringDamper>
      <mu1>100000</mu1>
      <mu2>100000</mu2>
      <kp>100000000.0</kp>
      <kd>1.0</kd>
    </gazebo>-->
    <link name="right_finger_tip">
        <inertial>
            <origin rpy="0 0 0" xyz="0.000299999999999317 0.0160078233491243 -0.0136945669206257" />
            <mass value="0.0104003125914103" />
            <inertia ixx="2.71909453810972E-06" ixy="0.0" ixz="0.0" iyy="7.69100314106116E-07" iyz="0.0" izz="2.30315190420171E-06" />
        </inertial>
        <visual>
            <origin rpy="0 0 0" xyz="0 0.02 -0.05" />
            <geometry>
                <mesh filename="package://owr_description/meshes/gripper/robotiq_arg2f_140_finger_tip.dae" scale="1.0 1.0 1.0" />
            </geometry>
            <material name="">
                <color rgba="0.1 0.1 0.1 1" />
            </material>
        </visual>
        <collision>
            <origin rpy="0 0 0" xyz="0 0 0" />
            <geometry>
                <mesh filename="package://owr_description/meshes/gripper/robotiq_arg2f_140_finger_tip.dae" scale="1.0 1.0 1.0" />
            </geometry>
        </collision>
    </link>
    <!--<gazebo reference="${prefix}${fingerprefix}_finger_tip">
      <selfCollide>true</selfCollide>
      <gravity>false</gravity>
      <implicitSpringDamper>1</implicitSpringDamper>
      <mu1>100000</mu1>
      <mu2>100000</mu2>
      <kp>100000000.0</kp>
      <kd>1.0</kd>
    </gazebo>-->
    <joint name="finger_joint" type="revolute">
        <origin rpy="2.4707963267948965 0 0" xyz="0 -0.030601 0.054905" />
        <parent link="robotiq_arg2f_base_link" />
        <child link="left_outer_knuckle" />
        <axis xyz="-1 0 0" />
        <!-- <limit lower="-3.14159" upper="3.14159" velocity="2.0" effort="1000" /> -->
        <limit effort="1000" lower="0" upper="0.775" velocity="2.0" />
    </joint>
    <joint name="left_outer_finger_joint" type="fixed">
        <origin rpy="0 0 0" xyz="0 0.01821998610742 0.0260018192872234" />
        <parent link="left_outer_knuckle" />
        <child link="left_outer_finger" />
        <axis xyz="1 0 0" />
    </joint>
    <joint name="left_inner_knuckle_joint" type="revolute">
        <origin rpy="2.4707963267948965 0 0.0" xyz="0 -0.0127 0.06142" />
        <parent link="robotiq_arg2f_base_link" />
        <child link="left_inner_knuckle" />
        <axis xyz="1 0 0" />
        <!--<limit lower="0" upper="0.8757" velocity="2.0" effort="1000" /> -->
        <limit effort="1000" lower="-3.14159" upper="3.14159" velocity="2.0" />
        <mimic joint="finger_joint" multiplier="-1" offset="0" />
    </joint>
    <joint name="left_inner_finger_joint" type="revolute">
        <origin rpy="-0.9 0 0" xyz="0 0.0817554015893473 -0.0282203446692936" />
        <parent link="left_outer_finger" />
        <child link="left_inner_finger" />
        <axis xyz="1 0 0" />
        <limit effort="1000" lower="-3.14159" upper="3.14159" velocity="2.0" />
        <!-- <limit lower="0" upper="0.8757" velocity="2.0" effort="1000" /> -->
        <mimic joint="finger_joint" multiplier="1" offset="0" />
    </joint>
    <joint name="left_finger_tip_joint" type="fixed">
        <origin rpy="0 0 0" xyz="0 0.01821998610742 0.0260018192872234" />
        <parent link="left_inner_finger" />
        <child link="left_finger_tip" />
        <axis xyz="1 0 0" />
    </joint>
    <joint name="right_outer_knuckle_joint" type="revolute">
        <origin rpy="2.4707963267948965 0 3.141592653589793" xyz="0 0.030601 0.054905" />
        <parent link="robotiq_arg2f_base_link" />
        <child link="right_outer_knuckle" />
        <axis xyz="1 0 0" />
        <!-- <limit lower="0" upper="0.725" velocity="2.0" effort="1000" /> -->
        <limit effort="1000" lower="-3.14159" upper="3.14159" velocity="2.0" />
        <mimic joint="finger_joint" multiplier="-1" offset="0" />
    </joint>
    <joint name="right_outer_finger_joint" type="fixed">
        <origin rpy="0 0 0" xyz="0 0.01821998610742 0.0260018192872234" />
        <parent link="right_outer_knuckle" />
        <child link="right_outer_finger" />
        <axis xyz="1 0 0" />
    </joint>
    <joint name="right_inner_knuckle_joint" type="revolute">
        <origin rpy="2.4707963267948965 0 -3.141592653589793" xyz="0 0.0127 0.06142" />
        <parent link="robotiq_arg2f_base_link" />
        <child link="right_inner_knuckle" />
        <axis xyz="1 0 0" />
        <!--<limit lower="0" upper="0.8757" velocity="2.0" effort="1000" /> -->
        <limit effort="1000" lower="-3.14159" upper="3.14159" velocity="2.0" />
        <mimic joint="finger_joint" multiplier="-1" offset="0" />
    </joint>
    <joint name="right_inner_finger_joint" type="revolute">
        <origin rpy="-0.9 0 0" xyz="0 0.0817554015893473 -0.0282203446692936" />
        <parent link="right_outer_finger" />
        <child link="right_inner_finger" />
        <axis xyz="1 0 0" />
        <limit effort="1000" lower="-3.14159" upper="3.14159" velocity="2.0" />
        <!-- <limit lower="0" upper="0.8757" velocity="2.0" effort="1000" /> -->
        <mimic joint="finger_joint" multiplier="1" offset="0" />
    </joint>
    <joint name="right_finger_tip_joint" type="fixed">
        <origin rpy="0 0 0" xyz="0 0.01821998610742 0.0260018192872234" />
        <parent link="right_inner_finger" />
        <child link="right_finger_tip" />
        <axis xyz="1 0 0" />
    </joint>
    <transmission name="finger_joint_trans">
        <type>transmission_interface/SimpleTransmission</type>
        <joint name="finger_joint">
            <hardwareInterface>hardware_interface/PositionJointInterface</hardwareInterface>
        </joint>
        <actuator name="finger_joint_motor">
            <mechanicalReduction>1</mechanicalReduction>
            <hardwareInterface>hardware_interface/EffortJointInterface</hardwareInterface>
        </actuator>
    </transmission>
    <gazebo>
        <!-- loading plugin: mimic joints works in gazebo now-->
        <!--libroboticsgroup_gazebo_mimic_joint_plugin.so-->
        <plugin filename="libroboticsgroup_upatras_gazebo_mimic_joint_plugin.so" name="mimic_robotiq_140_4">
            <joint>finger_joint</joint>
            <mimicJoint>right_outer_knuckle_joint</mimicJoint>
            <multiplier>-1.0</multiplier>
        </plugin>
        <plugin filename="libroboticsgroup_upatras_gazebo_mimic_joint_plugin.so" name="mimic_robotiq_140_2">
            <joint>finger_joint</joint>
            <mimicJoint>left_inner_finger_joint</mimicJoint>
            <multiplier>1.0</multiplier>
            <!--<offset>0.0</offset>-->
        </plugin>
        <plugin filename="libroboticsgroup_upatras_gazebo_mimic_joint_plugin.so" name="mimic_robotiq_140_1">
            <joint>finger_joint</joint>
            <mimicJoint>right_inner_finger_joint</mimicJoint>
            <multiplier>1.0</multiplier>
        </plugin>
        <plugin filename="libroboticsgroup_upatras_gazebo_mimic_joint_plugin.so" name="mimic_robotiq_140_3">
            <joint>finger_joint</joint>
            <mimicJoint>left_inner_knuckle_joint</mimicJoint>
            <multiplier>-1.0</multiplier>
        </plugin>
        <plugin filename="libroboticsgroup_upatras_gazebo_mimic_joint_plugin.so" name="mimic_robotiq_140_5">
            <joint>finger_joint</joint>
            <mimicJoint>right_inner_knuckle_joint</mimicJoint>
            <multiplier>-1.0</multiplier>
        </plugin>
    </gazebo>
    <joint name="owr_EEF_Link_gripper_base" type="fixed">
        <parent link="fts_toolside" />
        <child link="robotiq_arg2f_base_link" />
        <origin rpy="0.0 0.0 1.5707963267948966" xyz=" 0.0 0.0 0.0" />
    </joint>
    <!--<link name="${prefix}tool" />
      <joint name="tool_tip" type="fixed">
        <parent link= "${prefix}EEF_Link" />
        <child link = "${prefix}tool" />
        <origin xyz=" 0.00 0.0 0.2" rpy="0.0 0.0 0.0" />
      </joint>-->
    <transmission name="trans_left_inner_knuckle_joint">
        <type>transmission_interface/SimpleTransmission</type>
        <joint name="left_inner_knuckle_joint">
            <hardwareInterface>hardware_interface/EffortJointInterface</hardwareInterface>
        </joint>
        <actuator name="left_inner_knuckle_joint_motor">
            <hardwareInterface>hardware_interface/EffortJointInterface</hardwareInterface>
            <mechanicalReduction>1</mechanicalReduction>
        </actuator>
    </transmission>
    <transmission name="trans_left_inner_finger_joint">
        <type>transmission_interface/SimpleTransmission</type>
        <joint name="left_inner_finger_joint">
            <hardwareInterface>hardware_interface/EffortJointInterface</hardwareInterface>
        </joint>
        <actuator name="left_inner_finger_joint_motor">
            <hardwareInterface>hardware_interface/EffortJointInterface</hardwareInterface>
            <mechanicalReduction>1</mechanicalReduction>
        </actuator>
    </transmission>
    <transmission name="trans_right_outer_knuckle_joint">
        <type>transmission_interface/SimpleTransmission</type>
        <joint name="right_outer_knuckle_joint">
            <hardwareInterface>hardware_interface/EffortJointInterface</hardwareInterface>
        </joint>
        <actuator name="right_outer_knuckle_joint_motor">
            <hardwareInterface>hardware_interface/EffortJointInterface</hardwareInterface>
            <mechanicalReduction>1</mechanicalReduction>
        </actuator>
    </transmission>
    <transmission name="trans_right_inner_knuckle_joint">
        <type>transmission_interface/SimpleTransmission</type>
        <joint name="right_inner_knuckle_joint">
            <hardwareInterface>hardware_interface/EffortJointInterface</hardwareInterface>
        </joint>
        <actuator name="right_inner_knuckle_joint_motor">
            <hardwareInterface>hardware_interface/EffortJointInterface</hardwareInterface>
            <mechanicalReduction>1</mechanicalReduction>
        </actuator>
    </transmission>
    <transmission name="trans_right_inner_finger_joint">
        <type>transmission_interface/SimpleTransmission</type>
        <joint name="right_inner_finger_joint">
            <hardwareInterface>hardware_interface/EffortJointInterface</hardwareInterface>
        </joint>
        <actuator name="right_inner_finger_joint_motor">
            <hardwareInterface>hardware_interface/EffortJointInterface</hardwareInterface>
            <mechanicalReduction>1</mechanicalReduction>
        </actuator>
    </transmission>
</robot>

